Workbook

Sheet Nueva EPS
A1: PROGRAMA | B1: TIPO INDICADOR | C1: NOMBRE INDICADOR | D1: NUMERADOR | E1: DENOMINADOR | F1: POBLACION CORTE 31/12/2025 | G1: ESTIMACION | H1: META AÑO 2026 | I1: LINEA BASE 2025 | J1: ENERO | K1: FEBRERO | L1: MARZO | M1: ABRIL | N1: MAYO | O1: JUNIO | P1: JULIO | Q1: AGOSTO | R1: SEPTIEMBRE | S1: OCTUBRE | T1: NOVIEMBRE | U1: DICIEMBRE | V1: ACUMULADO ACTIVIDADES | W1: % EJECUCION | X1: POBLACION REPORTADA POR LA EPS
A2: DT cervix | B2: COBERTURA CCU | C2: Proporción de mujeres entre 25 y 29 años tamizadas para cáncer de cuello uterino con citologia cervico uterina. | D2: # Mujeres de 25 a 29 años, con toma de citologia cervico uterina en el periodo evaluado. | E2: Total de mujeres entre 25 y 29 años afiliadas a la EAPB en el municipio | F2: 3208 | G2: 0.33 | H2: =F2*0.33 -> 1058.64 | I2: 73,51% | J2: 77 | K2: 70 | V2: =SUM(J2:U2) -> 147 | W2: =V2/H2 -> 0.1388574 | X2: 3117
A3: DT cervix | B3: POSITIVIDAD CCU | C3: Proporción de citologias anormales en mujeres de 25 a 65 años en el periodo evaluado. | D3: # Mujeres de 25 a 65 años con citologia cervico uterina anormal o citologia de triage anormal en el periodo evaluado. | E3: Total de mujeres tamizadas con citologia cervico uterina o citologia de triage en el periodo evaluado. | F3: N/A | G3: 1 | H3: 1 | J3: 1 | K3: 2 | L3: 2 | V3: =SUM(J3:U3) -> 5 | W3: =V3/V2 -> 0.034013605
A4: DT cervix | B4: COBERTURA ADN VPH | C4: Proporción de mujeres entre 30 y 65 años tamizadas para cáncer de cuello uterino con ADN-VPH, según esquema en el periodo evaluado. | D4: # Mujeres de 30 a 65 años tamizadas con ADN VPH. | E4: Total de mujeres entre 30 y 65 años afiliadas a la EAPB en el municipio | F4: 18802 | G4: 0.2 | H4: =F4*0.2 -> 3760.4 | I4: 8,03% | J4: 20 | K4: 22 | V4: =SUM(J4:U4) -> 42 | W4: =V4/H4 -> 0.011169025
A5: DT cervix | B5: POSITIVIDAD ADN VPH | C5: Proporción de ADN VPH Positivo en el periodo evaluado | D5: Número de mujeres entre 30 y 65 años con resultado positivo para ADN-VPH durante el período de medición. | E5: Total de mujeres entre 30 y 65 años con resultado de ADN -VPH durante el periodo en revision | F5: N/A | G5: 1 | H5: 1 | J5: 7 | K5: 10 | V5: =SUM(J5:U5) -> 17 | W5: =V5/V4 -> 0.4047619
A6: DT cervix | B6: COBERTURA COLPOSCOPIA Y BIOPSIA | C6: Proporción de mujeres con citología anormal o citología de triage anormal a quienes se realizó colposcopia y biopsia | D6: Número de mujeres con resultado colposcopia y biopsia cervical, durante el período de medición. | E6: Total de mujeres con citología anormal o citología de triage anormal durante el mismo período de medición, requerían colposcopia y biopsia. | F6: N/A | G6: 1 | H6: 1 | J6: 1 | K6: 2 | L6: 2 | V6: =SUM(J6:U6) -> 5 | W6: =V6/V3 -> 1
A7: DT mama | B7: COBERTURA EXAMEN CLINICO DE LA MAMA | C7: Proporción de mujeres entre 40 y 69 años tamizadas con examen clínico de la mama en el periodo evaluado | D7: Número de mujeres entre 40 y 69 años a quienes se les realizó examen clínico de la mama en el periodo evaluado. | E7: Total de mujeres entre 40 y 69 años afiliadas a la EAPB en el municipio | F7: 14827 | G7: 1 | H7: =F7*1 -> 14827 | J7: 451 | K7: 501 | V7: =SUM(J7:U7) -> 952 | W7: =V7/H7 -> 0.06420719 | X7: 15344
A8: DT mama | B8: COBERTURA MAMOGRAFIA | C8: Proporción de mujeres entre 50 y 69 años tamizadas para cáncer de mama con mamografía en el periodo evaluado. | D8: Número de mujeres entre 50 y 69 años a quienes se les realizó toma de mamografia. | E8: Total de mujeres entre 50 y 69 años afiliadas a la EAPB en el municipio | F8: 9972 | G8: 0.5 | H8: =F8*0.5 -> 4986 | I8: 54,68% | J8: 235 | K8: 304 | V8: =SUM(J8:U8) -> 539 | W8: =V8/H8 -> 0.10810269 | X8: 10418
A9: DT mama | B9: POSITIVIDAD MAMOGRAFIA | C9: Proporción de mujeres entre 50 y 69 años tamizadas para cáncer de mama con reporte anormal de mamografía en el periodo evaluado. | D9: Número de mujeres entre 50 y 69 años con resultado de mamografia BI-RADS 4 o más | E9: Total de mujeres entre 50 y 69 años con toma de mamografia | F9: N/A | G9: 1 | H9: 1 | J9: 0 | K9: 1 | V9: =SUM(J9:U9) -> 1 | W9: =V9/V8 -> 0.0018552876
A10: DT mama | B10: COBERTURA BIOPSIA DE MAMA | C10: Proporción de mujeres con resultados de Biopsia de mama. | D10: Número de mujeres con mamografía reportada como BI-RADS 4, o más quienes se les realizó biopsia, durante el período evaluado. | E10: Total de mujeres con mamografía clasificada como BI-RADS 4 o superior, que requerían biopsia diagnóstica, durante el mismo período de medición. | F10: N/A | G10: 1 | H10: 1 | J10: 0 | K10: 1 | V10: =SUM(J10:U10) -> 1 | W10: =V10/V8 -> 0.0018552876
A11: DT Prostata | B11: COBERTURA TACTO RECTAL | C11: Proporción de hombres entre 50 y 75 años con tacto rectal | D11: Número de hombres entre 50 y 75 años a quienes se les realizó tacto rectal durante el período de medición | E11: Total de hombres entre 50 y 75 años afiliados a la EAPB en el municipio | F11: 9593 | G11: 0.2 | H11: =F11*0.2 -> 1918.6 | I11: 52,62% | J11: 81 | K11: 115 | V11: =SUM(J11:U11) -> 196 | W11: =V11/H11 -> 0.10215782 | X11: 10170
A12: DT Prostata | B12: COBERTURA PSA | C12: Proporción de hombres entre 50 y 75 años tamizados con PSA | D12: Número de hombres entre 50 y 75 años a quienes se les realizó PSA durante el período de medición | E12: Total de hombres entre 50 y 75 años afiliados a la EAPB en el municipio | F12: 9593 | G12: 0.2 | H12: =F12*0.2 -> 1918.6 | I12: 43,27% | J12: 62 | K12: 96 | V12: =SUM(J12:U12) -> 158 | W12: =V12/H12 -> 0.082351715
A13: DT Prostata | B13: COBERTURA (PSA Y TACTO RECTAL) | C13: Proporción de hombres mayores de 50 años con tamizaje combinado para cáncer de próstata (PSA y Tacto Rectal) | D13: Número de hombres entre 50 y 75 años a quienes se les realizó tamizaje combinado (PSA y tacto rectal) durante el período de medición | E13: Total de hombres entre 50 y 75 años afiliados a la EAPB en el municipio | F13: 9593 | G13: 0.2 | H13: =F13*0.2 -> 1918.6 | I13: 30,09% | J13: 62 | K13: 96 | V13: =SUM(J13:U13) -> 158 | W13: =V13/H13 -> 0.082351715
A14: DT Prostata | B14: POSITIVIDAD CANCER DE PROSTATA | C14: Proporción de hombres mayores de 50 años con tamizacion de cancer de prostata resultado anormal | D14: Numero de hombres con resultado anormal de tamizacion para cancer de prostata en el periodo evaluado. | E14: Total de hombres con alguna prueba de tamizacion para cáncer de prostata | F14: N/A | G14: 1 | H14: 1 | J14: 6 | K14: 11 | V14: =SUM(J14:U14) -> 17 | W14: =V14/V13 -> 0.10759494
A15: DT Prostata | B15: COBERTURA BIOPSIA DE PROSTATA | C15: Proporción de hombres con pruebas de tamizaje anormal a quienes se les realizó biopsia de próstata | D15: Número de hombres con resultado anormal en pruebas de tamizaje para cáncer de próstata (PSA o tacto rectal) a quienes se les realizó biopsia de próstata durante el período de medición | E15: Total de hombres con resultado anormal en pruebas de tamizaje para cáncer de próstata durante el mismo período de medición, que según criterio clínico requerían biopsia prostática | F15: N/A | G15: 1 | H15: 1 | J15: SD | K15: SD | V15: =SUM(J15:U15) -> 0 | W15: =V15/V14 -> 0
A16: DT Colon y Recto | B16: COBERTURA TAMIZACION SANGRE OCULTA EN HECES | C16: Proporción de personas entre 50 y 75 años tamizadas para cáncer de colon y recto (sangre oculta en materia fecal con inmunoquímica) | D16: Número de personas entre 50 y 75 años a quienes se les realizó prueba de sangre oculta en materia fecal por método inmunoquímico. | E16: Total de personas entre 50 y 75 años en el municipio | F16: 21667 | G16: 0.5 | H16: =F16*0.5 -> 10833.5 | I16: 46,69% | J16: 381 | K16: 613 | V16: =SUM(J16:U16) -> 994 | W16: =V16/H16 -> 0.091752435
A17: DT Colon y Recto | B17: POSITIVIDAD SANGRE OCULTA EN HECES | C17: Proporción de personas con pruebas anormal de sangre oculta en heces. | D17: Total de personas entre 50 y 75 años con tamizaje resultado positivo de sangre oculta. | E17: Total de personas entre 50 y 75 años con tamizaje de sangre oculta en heces | F17: N/A | G17: 1 | H17: 1 | J17: 14 | K17: 34 | V17: =SUM(J17:U17) -> 48 | W17: =V17/V16 -> 0.048289738
A18: DT Colon y Recto | B18: COBERTURA COLONOSCOPIA | C18: Proporción de personas mayores de 50 años con test de sangre oculta en materia fecal positivos a los que se les realizó colonoscopia | D18: Número de personas de 50 años o más con resultado positivo en la prueba de sangre oculta en materia fecal a quienes se les realizó colonoscopia diagnóstica posterior al resultado positivo, durante el período de medición | E18: Total de personas de 50 años o más con resultado positivo en la prueba de sangre oculta en materia fecal durante el mismo período de medición, que requerían colonoscopia diagnóstica según el lineamiento técnico | F18: N/A | G18: 1 | H18: 1 | J18: 0 | K18: 0 | V18: =SUM(J18:U18) -> 0 | W18: =V18/V17 -> 0
A21: Seguimiento
A22: 46129 | B22: Paola Gallo
A23: No se dispone de Indicadores del mes de marzo
A24: Validar los resultados de ADN VPH para identificar usuarias para CCU y Colposcopia
A25: 1 caso Birad 5 . CC 23770324 biopsia de mama 03/03//2026 en manejo con Centro Cancerologico de Boyaca
A26: Verificar de los resultados positivos de PSA , si se realizo biopsia
A27: no se tiene realizacion de colonoscopia, ante resultados de SOMF positivos

Sheet Sanitas
A1: PROGRAMA | B1: TIPO INDICADOR | C1: NOMBRE INDICADOR | D1: NUMERADOR | E1: DENOMINADOR | F1: POBLACION CORTE 31/12/2025 | G1: ESTIMACION | H1: META AÑO 2026 | I1: LINEA BASE 2025 | J1: ENERO | K1: FEBRERO | L1: MARZO | M1: ABRIL | N1: MAYO | O1: JUNIO | P1: JULIO | Q1: AGOSTO | R1: SEPTIEMBRE | S1: OCTUBRE | T1: NOVIEMBRE | U1: DICIEMBRE | V1: ACUMULADO ACTIVIDADES | W1: % EJECUCION
A2: DT cervix | B2: COBERTURA CCU | C2: Proporción de mujeres entre 25 y 29 años tamizadas para cáncer de cuello uterino con citologia cervico uterina. | D2: # Mujeres de 25 a 29 años, con toma de citologia cervico uterina en el periodo evaluado. | E2: Total de mujeres entre 25 y 29 años afiliadas a la EAPB en el municipio | F2: 1280 | G2: 0.33 | H2: =F2*0.33 -> 422.4 | J2: 142 | K2: 138 | L2: 175 | V2: =SUM(J2:U2) -> 455 | W2: =V2/H2 -> 1.077178
A3: DT cervix | B3: POSITIVIDAD CCU | C3: Proporción de citologias anormales en mujeres de 25 a 65 años en el periodo evaluado. | D3: # Mujeres de 25 a 65 años con citologia cervico uterina anormal o citologia de triage anormal en el periodo evaluado. | E3: Total de mujeres tamizadas con citologia cervico uterina o citologia de triage en el periodo evaluado. | F3: N/A | G3: 1 | H3: 1 | J3: 0 | K3: 0 | L3: 3 | V3: =SUM(J3:U3) -> 3 | W3: =V3/V2 -> 0.0065934066
A4: DT cervix | B4: COBERTURA ADN VPH | C4: Proporción de mujeres entre 30 y 65 años tamizadas para cáncer de cuello uterino con ADN-VPH, según esquema en el periodo evaluado. | D4: # Mujeres de 30 a 65 años tamizadas con ADN VPH. | E4: Total de mujeres entre 30 y 65 años afiliadas a la EAPB en el municipio | F4: 9805 | G4: 0.2 | H4: =F4*0.2 -> 1961 | I4: 12,47% | J4: 5 | K4: 0 | L4: 1 | V4: =SUM(J4:U4) -> 6 | W4: =V4/H4 -> 0.0030596634 | X4: 9990
A5: DT cervix | B5: POSITIVIDAD ADN VPH | C5: Proporción de ADN VPH Positivo en el periodo evaluado | D5: Número de mujeres entre 30 y 65 años con resultado positivo para ADN-VPH durante el período de medición. | E5: Total de mujeres entre 30 y 65 años con resultado de ADN -VPH durante el periodo en revision | F5: N/A | G5: 1 | H5: 1 | J5: 0 | K5: 0 | L5: 0 | V5: =SUM(J5:U5) -> 0 | W5: =V5/V4 -> 0
A6: DT cervix | B6: COBERTURA COLPOSCOPIA Y BIOPSIA | C6: Proporción de mujeres con citología anormal o citología de triage anormal a quienes se realizó colposcopia y biopsia | D6: Número de mujeres con resultado colposcopia y biopsia cervical, durante el período de medición. | E6: Total de mujeres con citología anormal o citología de triage anormal durante el mismo período de medición, requerían colposcopia y biopsia. | F6: N/A | G6: 1 | H6: 1 | J6: 0 | K6: 0 | L6: SD | V6: =SUM(J6:U6) -> 0 | W6: =V6/V3 -> 0
A7: DT mama | B7: COBERTURA EXAMEN CLINICO DE LA MAMA | C7: Proporción de mujeres entre 40 y 69 años tamizadas con examen clínico de la mama en el periodo evaluado | D7: Número de mujeres entre 40 y 69 años a quienes se les realizó examen clínico de la mama en el periodo evaluado. | E7: Total de mujeres entre 40 y 69 años afiliadas a la EAPB en el municipio | F7: 7151 | G7: 1 | H7: =F7*1 -> 7151 | J7: 16 | K7: 11 | L7: 8 | V7: =SUM(J7:U7) -> 35 | W7: =V7/H7 -> 0.0048944204
A8: DT mama | B8: COBERTURA MAMOGRAFIA | C8: Proporción de mujeres entre 50 y 69 años tamizadas para cáncer de mama con mamografía en el periodo evaluado. | D8: Número de mujeres entre 50 y 69 años a quienes se les realizó toma de mamografia. | E8: Total de mujeres entre 50 y 69 años afiliadas a la EAPB en el municipio | F8: 3910 | G8: 0.5 | H8: =F8*0.5 -> 1955 | I8: 58,59% | J8: 74 | K8: 78 | L8: 128 | V8: =SUM(J8:U8) -> 280 | W8: =V8/H8 -> 0.14322251
A9: DT mama | B9: POSITIVIDAD MAMOGRAFIA | C9: Proporción de mujeres entre 50 y 69 años tamizadas para cáncer de mama con reporte anormal de mamografía en el periodo evaluado. | D9: Número de mujeres entre 50 y 69 años con resultado de mamografia BI-RADS 4 o más | E9: Total de mujeres entre 50 y 69 años con toma de mamografia | F9: N/A | G9: 1 | H9: 1 | J9: 0 | K9: 1 | L9: 0 | V9: =SUM(J9:U9) -> 1 | W9: =V9/V8 -> 0.0035714286
A10: DT mama | B10: COBERTURA BIOPSIA DE MAMA | C10: Proporción de mujeres con resultados de Biopsia de mama. | D10: Número de mujeres con mamografía reportada como BI-RADS 4, o más quienes se les realizó biopsia, durante el período evaluado. | E10: Total de mujeres con mamografía clasificada como BI-RADS 4 o superior, que requerían biopsia diagnóstica, durante el mismo período de medición. | F10: N/A | G10: 1 | H10: 1 | J10: 0 | K10: 0 | L10: 0 | V10: =SUM(J10:U10) -> 0 | W10: =V10/V8 -> 0
A11: DT Prostata | B11: COBERTURA TACTO RECTAL | C11: Proporción de hombres entre 50 y 75 años con tacto rectal | D11: Número de hombres entre 50 y 75 años a quienes se les realizó tacto rectal durante el período de medición | E11: Total de hombres entre 50 y 75 años afiliados a la EAPB en el municipio | F11: 4071 | G11: 0.2 | H11: =F11*0.2 -> 814.2 | I11: 41,46% | J11: 97 | K11: 94 | V11: =SUM(J11:U11) -> 191 | W11: =V11/H11 -> 0.2345861 | X11: 4164
A12: DT Prostata | B12: COBERTURA PSA | C12: Proporción de hombres entre 50 y 75 años tamizados con PSA | D12: Número de hombres entre 50 y 75 años a quienes se les realizó PSA durante el período de medición | E12: Total de hombres entre 50 y 75 años afiliados a la EAPB en el municipio | F12: 4071 | G12: 0.2 | H12: =F12*0.2 -> 814.2 | I12: 55,89% | J12: 96 | K12: 90 | V12: =SUM(J12:U12) -> 186 | W12: =V12/H12 -> 0.2284451
A13: DT Prostata | B13: COBERTURA (PSA Y TACTO RECTAL) | C13: Proporción de hombres mayores de 50 años con tamizaje combinado para cáncer de próstata (PSA y Tacto Rectal) | D13: Número de hombres entre 50 y 75 años a quienes se les realizó tamizaje combinado (PSA y tacto rectal) durante el período de medición | E13: Total de hombres entre 50 y 75 años afiliados a la EAPB en el municipio | F13: 4071 | G13: 0.2 | H13: =F13*0.2 -> 814.2 | I13: 37,69% | J13: 16 | K13: 18 | V13: =SUM(J13:U13) -> 34 | W13: =V13/H13 -> 0.041758782
A14: DT Prostata | B14: POSITIVIDAD CANCER DE PROSTATA | C14: Proporción de hombres mayores de 50 años con tamizacion de cancer de prostata resultado anormal | D14: Numero de hombres con resultado anormal de tamizacion para cancer de prostata en el periodo evaluado. | E14: Total de hombres con alguna prueba de tamizacion para cáncer de prostata | F14: N/A | G14: 1 | H14: 1 | I14: 68,04% | J14: 1 | K14: 4 | V14: =SUM(J14:U14) -> 5 | W14: =V14/V13 -> 0.14705882
A15: DT Prostata | B15: COBERTURA BIOPSIA DE PROSTATA | C15: Proporción de hombres con pruebas de tamizaje anormal a quienes se les realizó biopsia de próstata | D15: Número de hombres con resultado anormal en pruebas de tamizaje para cáncer de próstata (PSA o tacto rectal) a quienes se les realizó biopsia de próstata durante el período de medición | E15: Total de hombres con resultado anormal en pruebas de tamizaje para cáncer de próstata durante el mismo período de medición, que según criterio clínico requerían biopsia prostática | F15: N/A | G15: 1 | H15: 1 | J15: SD | K15: SD | L15: SD | V15: =SUM(J15:U15) -> 0 | W15: =V15/V14 -> 0
A16: DT Colon y Recto | B16: COBERTURA TAMIZACION SANGRE OCULTA EN HECES | C16: Proporción de personas entre 50 y 75 años tamizadas para cáncer de colon y recto (sangre oculta en materia fecal con inmunoquímica) | D16: Número de personas entre 50 y 75 años a quienes se les realizó prueba de sangre oculta en materia fecal por método inmunoquímico. | E16: Total de personas entre 50 y 75 años en el municipio | F16: 8571 | G16: 0.5 | H16: =F16*0.5 -> 4285.5 | I16: 43,01% | J16: 140 | K16: 155 | V16: =SUM(J16:U16) -> 295 | W16: =V16/H16 -> 0.068836775
A17: DT Colon y Recto | B17: POSITIVIDAD SANGRE OCULTA EN HECES | C17: Proporción de personas con pruebas anormal de sangre oculta en heces. | D17: Total de personas entre 50 y 75 años con tamizaje resultado positivo de sangre oculta. | E17: Total de personas entre 50 y 75 años con tamizaje de sangre oculta en heces | F17: N/A | G17: 1 | H17: 1 | J17: 0 | K17: 0 | V17: =SUM(J17:U17) -> 0 | W17: =V17/V16 -> 0
A18: DT Colon y Recto | B18: COBERTURA COLONOSCOPIA | C18: Proporción de personas mayores de 50 años con test de sangre oculta en materia fecal positivos a los que se les realizó colonoscopia | D18: Número de personas de 50 años o más con resultado positivo en la prueba de sangre oculta en materia fecal a quienes se les realizó colonoscopia diagnóstica posterior al resultado positivo, durante el período de medición | E18: Total de personas de 50 años o más con resultado positivo en la prueba de sangre oculta en materia fecal durante el mismo período de medición, que requerían colonoscopia diagnóstica según el lineamiento técnico | F18: N/A | G18: 1 | H18: 1 | J18: 0 | K18: 0 | V18: =SUM(J18:U18) -> 0 | W18: =V18/V17 -> #DIV/0!
A22: Seguimiento
A23: 46129 | B23: Mamografia con birad 5 , ene l mes de febrero con servicio autorizado para biopsia sin realizacioni de la misma CC 24226148 . Meiby Garnica de Neira | D23: Seguimiento 17/04/2026
B24: No se tiene reporte de biopsia en hombres con tamizaje de prostata anormal
B25: Solicitar a la lider nacional para definir en el censo los casos activos.
B26: Ala fecha no se cuenta con indicadoress finales del mes de marzo, los ingresados son premilinares.

Sheet Coosalud
A1: PROGRAMA | B1: TIPO INDICADOR | C1: NOMBRE INDICADOR | D1: NUMERADOR | E1: DENOMINADOR | F1: POBLACION CORTE 31/12/2025 | G1: ESTIMACION | H1: META AÑO 2026 | I1: LINEA BASE 2025 | J1: ENERO | K1: FEBRERO | L1: MARZO | M1: ABRIL | N1: MAYO | O1: JUNIO | P1: JULIO | Q1: AGOSTO | R1: SEPTIEMBRE | S1: OCTUBRE | T1: NOVIEMBRE | U1: DICIEMBRE | V1: ACUMULADO ACTIVIDADES | W1: % EJECUCION
A2: DT cervix | B2: COBERTURA CCU | C2: Proporción de mujeres entre 25 y 29 años tamizadas para cáncer de cuello uterino con citologia cervico uterina. | D2: # Mujeres de 25 a 29 años, con toma de citologia cervico uterina en el periodo evaluado. | E2: Total de mujeres entre 25 y 29 años afiliadas a la EAPB en el municipio | F2: 432 | G2: 0.33 | H2: =F2*0.33 -> 142.56 | I2: 74,0% | J2: 14 | K2: 9 | L2: 10 | V2: =SUM(J2:U2) -> 33 | W2: =V2/H2 -> 0.23148148
A3: DT cervix | B3: POSITIVIDAD CCU | C3: Proporción de citologias anormales en mujeres de 25 a 65 años en el periodo evaluado. | D3: # Mujeres de 25 a 65 años con citologia cervico uterina anormal o citologia de triage anormal en el periodo evaluado. | E3: Total de mujeres tamizadas con citologia cervico uterina o citologia de triage en el periodo evaluado. | F3: N/A | G3: 1 | H3: 1 | J3: 2 | K3: 2 | L3: 0 | V3: =SUM(J3:U3) -> 4 | W3: =V3/V2 -> 0.12121212
A4: DT cervix | B4: COBERTURA ADN VPH | C4: Proporción de mujeres entre 30 y 65 años tamizadas para cáncer de cuello uterino con ADN-VPH, según esquema en el periodo evaluado. | D4: # Mujeres de 30 a 65 años tamizadas con ADN VPH. | E4: Total de mujeres entre 30 y 65 años afiliadas a la EAPB en el municipio | F4: 2598 | G4: 0.2 | H4: =F4*0.2 -> 519.6 | I4: 21,5% | J4: 39 | K4: 7 | L4: 7 | V4: =SUM(J4:U4) -> 53 | W4: =V4/H4 -> 0.10200154
A5: DT cervix | B5: POSITIVIDAD ADN VPH | C5: Proporción de ADN VPH Positivo en el periodo evaluado | D5: Número de mujeres entre 30 y 65 años con resultado positivo para ADN-VPH durante el período de medición. | E5: Total de mujeres entre 30 y 65 años con resultado de ADN -VPH durante el periodo en revision | F5: N/A | G5: 1 | H5: 1 | J5: 2 | K5: 0 | L5: 0 | V5: =SUM(J5:U5) -> 2 | W5: =V5/V4 -> 0.037735849
A6: DT cervix | B6: COBERTURA COLPOSCOPIA Y BIOPSIA | C6: Proporción de mujeres con citología anormal o citología de triage anormal a quienes se realizó colposcopia y biopsia | D6: Número de mujeres con resultado colposcopia y biopsia cervical, durante el período de medición. | E6: Total de mujeres con citología anormal o citología de triage anormal durante el mismo período de medición, requerían colposcopia y biopsia. | F6: N/A | G6: 1 | H6: 1 | J6: 1 | K6: 0 | L6: 0 | V6: =SUM(J6:U6) -> 1 | W6: =V6/V3 -> 0.25
A7: DT mama | B7: COBERTURA EXAMEN CLINICO DE LA MAMA | C7: Proporción de mujeres entre 40 y 69 años tamizadas con examen clínico de la mama en el periodo evaluado | D7: Número de mujeres entre 40 y 69 años a quienes se les realizó examen clínico de la mama en el periodo evaluado. | E7: Total de mujeres entre 40 y 69 años afiliadas a la EAPB en el municipio | F7: 1922 | G7: 1 | H7: =F7*1 -> 1922 | J7: 24 | K7: 64 | L7: 30 | V7: =SUM(J7:U7) -> 118 | W7: =V7/H7 -> 0.061394381
A8: DT mama | B8: COBERTURA MAMOGRAFIA | C8: Proporción de mujeres entre 50 y 69 años tamizadas para cáncer de mama con mamografía en el periodo evaluado. | D8: Número de mujeres entre 50 y 69 años a quienes se les realizó toma de mamografia. | E8: Total de mujeres entre 50 y 69 años afiliadas a la EAPB en el municipio | F8: 1075 | G8: 0.5 | H8: =F8*0.5 -> 537.5 | I8: 67,1% | J8: 15 | K8: 8 | L8: 20 | V8: =SUM(J8:U8) -> 43 | W8: =V8/H8 -> 0.08
A9: DT mama | B9: POSITIVIDAD MAMOGRAFIA | C9: Proporción de mujeres entre 50 y 69 años tamizadas para cáncer de mama con reporte anormal de mamografía en el periodo evaluado. | D9: Número de mujeres entre 50 y 69 años con resultado de mamografia BI-RADS 4 o más | E9: Total de mujeres entre 50 y 69 años con toma de mamografia | F9: N/A | G9: 1 | H9: 1 | J9: 0 | K9: 0 | L9: 0 | V9: =SUM(J9:U9) -> 0 | W9: =V9/V8 -> 0
A10: DT mama | B10: COBERTURA BIOPSIA DE MAMA | C10: Proporción de mujeres con resultados de Biopsia de mama. | D10: Número de mujeres con mamografía reportada como BI-RADS 4, o más quienes se les realizó biopsia, durante el período evaluado. | E10: Total de mujeres con mamografía clasificada como BI-RADS 4 o superior, que requerían biopsia diagnóstica, durante el mismo período de medición. | F10: N/A | G10: 1 | H10: 1 | J10: 0 | K10: 0 | L10: 0 | V10: =SUM(J10:U10) -> 0 | W10: =V10/V8 -> 0
A11: DT Prostata | B11: COBERTURA TACTO RECTAL | C11: Proporción de hombres entre 50 y 75 años con tacto rectal | D11: Número de hombres entre 50 y 75 años a quienes se les realizó tacto rectal durante el período de medición | E11: Total de hombres entre 50 y 75 años afiliados a la EAPB en el municipio | F11: 949 | G11: 0.2 | H11: =F11*0.2 -> 189.8 | I11: 43,53% | J11: 22 | K11: 15 | L11: 8 | V11: =SUM(J11:U11) -> 45 | W11: =V11/H11 -> 0.23709168
A12: DT Prostata | B12: COBERTURA PSA | C12: Proporción de hombres entre 50 y 75 años tamizados con PSA | D12: Número de hombres entre 50 y 75 años a quienes se les realizó PSA durante el período de medición | E12: Total de hombres entre 50 y 75 años afiliados a la EAPB en el municipio | F12: 949 | G12: 0.2 | H12: =F12*0.2 -> 189.8 | I12: 51,92% | J12: 6 | K12: 10 | L12: 13 | V12: =SUM(J12:U12) -> 29 | W12: =V12/H12 -> 0.15279241
A13: DT Prostata | B13: COBERTURA (PSA Y TACTO RECTAL) | C13: Proporción de hombres mayores de 50 años con tamizaje combinado para cáncer de próstata (PSA y Tacto Rectal) | D13: Número de hombres entre 50 y 75 años a quienes se les realizó tamizaje combinado (PSA y tacto rectal) durante el período de medición | E13: Total de hombres entre 50 y 75 años afiliados a la EAPB en el municipio | F13: 949 | G13: 0.2 | H13: =F13*0.2 -> 189.8 | I13: 21,78% | J13: 4 | K13: 1 | L13: 1 | V13: =SUM(J13:U13) -> 6 | W13: =V13/H13 -> 0.031612223
A14: DT Prostata | B14: POSITIVIDAD CANCER DE PROSTATA | C14: Proporción de hombres mayores de 50 años con tamizacion de cancer de prostata resultado anormal | D14: Numero de hombres con resultado anormal de tamizacion para cancer de prostata en el periodo evaluado. | E14: Total de hombres con alguna prueba de tamizacion para cáncer de prostata | F14: N/A | G14: 1 | H14: 1 | J14: 0 | K14: 0 | L14: 1 | V14: =SUM(J14:U14) -> 1 | W14: =V14/V13 -> 0.16666667
A15: DT Prostata | B15: COBERTURA BIOPSIA DE PROSTATA | C15: Proporción de hombres con pruebas de tamizaje anormal a quienes se les realizó biopsia de próstata | D15: Número de hombres con resultado anormal en pruebas de tamizaje para cáncer de próstata (PSA o tacto rectal) a quienes se les realizó biopsia de próstata durante el período de medición | E15: Total de hombres con resultado anormal en pruebas de tamizaje para cáncer de próstata durante el mismo período de medición, que según criterio clínico requerían biopsia prostática | F15: N/A | G15: 1 | H15: 1 | J15: 0 | K15: 0 | L15: 0 | V15: =SUM(J15:U15) -> 0 | W15: =V15/V14 -> 0
A16: DT Colon y Recto | B16: COBERTURA TAMIZACION SANGRE OCULTA EN HECES | C16: Proporción de personas entre 50 y 75 años tamizadas para cáncer de colon y recto (sangre oculta en materia fecal con inmunoquímica) | D16: Número de personas entre 50 y 75 años a quienes se les realizó prueba de sangre oculta en materia fecal por método inmunoquímico. | E16: Total de personas entre 50 y 75 años en el municipio | F16: 2175 | G16: 0.5 | H16: =F16*0.5 -> 1087.5 | I16: 48,53% | J16: 16 | K16: 11 | L16: 10 | V16: =SUM(J16:U16) -> 37 | W16: =V16/H16 -> 0.034022989
A17: DT Colon y Recto | B17: POSITIVIDAD SANGRE OCULTA EN HECES | C17: Proporción de personas con pruebas anormal de sangre oculta en heces. | D17: Total de personas entre 50 y 75 años con tamizaje resultado positivo de sangre oculta. | E17: Total de personas entre 50 y 75 años con tamizaje de sangre oculta en heces | F17: N/A | G17: 1 | H17: 1 | J17: 0 | K17: 2 | L17: 1 | V17: =SUM(J17:U17) -> 3 | W17: =V17/V16 -> 0.081081081
A18: DT Colon y Recto | B18: COBERTURA COLONOSCOPIA | C18: Proporción de personas mayores de 50 años con test de sangre oculta en materia fecal positivos a los que se les realizó colonoscopia | D18: Número de personas de 50 años o más con resultado positivo en la prueba de sangre oculta en materia fecal a quienes se les realizó colonoscopia diagnóstica posterior al resultado positivo, durante el período de medición | E18: Total de personas de 50 años o más con resultado positivo en la prueba de sangre oculta en materia fecal durante el mismo período de medición, que requerían colonoscopia diagnóstica según el lineamiento técnico | F18: N/A | G18: 1 | H18: 1 | J18: 0 | K18: 2 | L18: 1 | V18: =SUM(J18:U18) -> 3 | W18: =V18/V17 -> 1

Sheet Famisanar
A1: PROGRAMA | B1: TIPO INDICADOR | C1: NOMBRE INDICADOR | D1: NUMERADOR | E1: DENOMINADOR | F1: POBLACION CORTE 31/12/2025 | G1: ESTIMACION | H1: META AÑO 2026 | I1: LINEA BASE 2025 | J1: ENERO | K1: FEBRERO | L1: MARZO | M1: ABRIL | N1: MAYO | O1: JUNIO | P1: JULIO | Q1: AGOSTO | R1: SEPTIEMBRE | S1: OCTUBRE | T1: NOVIEMBRE | U1: DICIEMBRE | V1: ACUMULADO ACTIVIDADES | W1: % EJECUCION
A2: DT cervix | B2: COBERTURA CCU | C2: Proporción de mujeres entre 25 y 29 años tamizadas para cáncer de cuello uterino con citologia cervico uterina. | D2: # Mujeres de 25 a 29 años, con toma de citologia cervico uterina en el periodo evaluado. | E2: Total de mujeres entre 25 y 29 años afiliadas a la EAPB en el municipio | F2: 452 | G2: 0.33 | H2: =F2*0.33 -> 149.16 | J2: 4 | K2: 9 | V2: =SUM(J2:U2) -> 13 | W2: =V2/H2 -> 0.087154733
A3: DT cervix | B3: POSITIVIDAD CCU | C3: Proporción de citologias anormales en mujeres de 25 a 65 años en el periodo evaluado. | D3: # Mujeres de 25 a 65 años con citologia cervico uterina anormal o citologia de triage anormal en el periodo evaluado. | E3: Total de mujeres tamizadas con citologia cervico uterina o citologia de triage en el periodo evaluado. | F3: N/A | G3: 1 | H3: 1 | J3: 2 | K3: 2 | V3: =SUM(J3:U3) -> 4 | W3: =V3/V2 -> 0.30769231 | X3: 3438
A4: DT cervix | B4: COBERTURA ADN VPH | C4: Proporción de mujeres entre 30 y 65 años tamizadas para cáncer de cuello uterino con ADN-VPH, según esquema en el periodo evaluado. | D4: # Mujeres de 30 a 65 años tamizadas con ADN VPH. | E4: Total de mujeres entre 30 y 65 años afiliadas a la EAPB en el municipio | F4: 3070 | G4: 0.2 | H4: =F4*0.2 -> 614 | I4: 52,15% | J4: 2 | K4: 55 | V4: =SUM(J4:U4) -> 57 | W4: =V4/H4 -> 0.092833876
A5: DT cervix | B5: POSITIVIDAD ADN VPH | C5: Proporción de ADN VPH Positivo en el periodo evaluado | D5: Número de mujeres entre 30 y 65 años con resultado positivo para ADN-VPH durante el período de medición. | E5: Total de mujeres entre 30 y 65 años con resultado de ADN -VPH durante el periodo en revision | F5: N/A | G5: 1 | H5: 1 | J5: 0 | K5: 6 | V5: =SUM(J5:U5) -> 6 | W5: =V5/V4 -> 0.10526316
A6: DT cervix | B6: COBERTURA COLPOSCOPIA Y BIOPSIA | C6: Proporción de mujeres con citología anormal o citología de triage anormal a quienes se realizó colposcopia y biopsia | D6: Número de mujeres con resultado colposcopia y biopsia cervical, durante el período de medición. | E6: Total de mujeres con citología anormal o citología de triage anormal durante el mismo período de medición, requerían colposcopia y biopsia. | F6: N/A | G6: 1 | H6: 1 | J6: 3 | K6: 0 | V6: =SUM(J6:U6) -> 3 | W6: =V6/V3 -> 0.75
A7: DT mama | B7: COBERTURA EXAMEN CLINICO DE LA MAMA | C7: Proporción de mujeres entre 40 y 69 años tamizadas con examen clínico de la mama en el periodo evaluado | D7: Número de mujeres entre 40 y 69 años a quienes se les realizó examen clínico de la mama en el periodo evaluado. | E7: Total de mujeres entre 40 y 69 años afiliadas a la EAPB en el municipio | F7: 2331 | G7: 1 | H7: =F7*1 -> 2331 | J7: 329 | K7: 441 | L7: 51 | V7: =SUM(J7:U7) -> 821 | W7: =V7/H7 -> 0.35220935 | X7: 2282
A8: DT mama | B8: COBERTURA MAMOGRAFIA | C8: Proporción de mujeres entre 50 y 69 años tamizadas para cáncer de mama con mamografía en el periodo evaluado. | D8: Número de mujeres entre 50 y 69 años a quienes se les realizó toma de mamografia. | E8: Total de mujeres entre 50 y 69 años afiliadas a la EAPB en el municipio | F8: 1332 | G8: 0.5 | H8: =F8*0.5 -> 666 | I8: 40,63% | J8: 53 | K8: 93 | L8: 24 | V8: =SUM(J8:U8) -> 170 | W8: =V8/H8 -> 0.25525526
A9: DT mama | B9: POSITIVIDAD MAMOGRAFIA | C9: Proporción de mujeres entre 50 y 69 años tamizadas para cáncer de mama con reporte anormal de mamografía en el periodo evaluado. | D9: Número de mujeres entre 50 y 69 años con resultado de mamografia BI-RADS 4 o más | E9: Total de mujeres entre 50 y 69 años con toma de mamografia | F9: N/A | G9: 1 | H9: 1 | J9: 0 | K9: 0 | L9: 0 | V9: =SUM(J9:U9) -> 0 | W9: =V9/V8 -> 0
A10: DT mama | B10: COBERTURA BIOPSIA DE MAMA | C10: Proporción de mujeres con resultados de Biopsia de mama. | D10: Número de mujeres con mamografía reportada como BI-RADS 4, o más quienes se les realizó biopsia, durante el período evaluado. | E10: Total de mujeres con mamografía clasificada como BI-RADS 4 o superior, que requerían biopsia diagnóstica, durante el mismo período de medición. | F10: N/A | G10: 1 | H10: 1 | J10: 0 | K10: 0 | L10: 0 | V10: =SUM(J10:U10) -> 0 | W10: =V10/V8 -> 0
A11: DT Prostata | B11: COBERTURA TACTO RECTAL | C11: Proporción de hombres entre 50 y 75 años con tacto rectal | D11: Número de hombres entre 50 y 75 años a quienes se les realizó tacto rectal durante el período de medición | E11: Total de hombres entre 50 y 75 años afiliados a la EAPB en el municipio | F11: 1452 | G11: 0.2 | H11: =F11*0.2 -> 290.4 | I11: 21,52% | J11: 45 | K11: 48 | L11: 68 | V11: =SUM(J11:U11) -> 161 | W11: =V11/H11 -> 0.55440771 | X11: 1424
A12: DT Prostata | B12: COBERTURA PSA | C12: Proporción de hombres entre 50 y 75 años tamizados con PSA | D12: Número de hombres entre 50 y 75 años a quienes se les realizó PSA durante el período de medición | E12: Total de hombres entre 50 y 75 años afiliados a la EAPB en el municipio | F12: 1452 | G12: 0.2 | H12: =F12*0.2 -> 290.4 | I12: 49,93% | J12: 27 | K12: 39 | L12: 11 | V12: =SUM(J12:U12) -> 77 | W12: =V12/H12 -> 0.26515152
A13: DT Prostata | B13: COBERTURA (PSA Y TACTO RECTAL) | C13: Proporción de hombres mayores de 50 años con tamizaje combinado para cáncer de próstata (PSA y Tacto Rectal) | D13: Número de hombres entre 50 y 75 años a quienes se les realizó tamizaje combinado (PSA y tacto rectal) durante el período de medición | E13: Total de hombres entre 50 y 75 años afiliados a la EAPB en el municipio | F13: 1452 | G13: 0.2 | H13: =F13*0.2 -> 290.4 | I13: 15,05% | J13: 4 | K13: 6 | L13: 0 | V13: =SUM(J13:U13) -> 10 | W13: =V13/H13 -> 0.034435262
A14: DT Prostata | B14: POSITIVIDAD CANCER DE PROSTATA | C14: Proporción de hombres mayores de 50 años con tamizacion de cancer de prostata resultado anormal | D14: Numero de hombres con resultado anormal de tamizacion para cancer de prostata en el periodo evaluado. | E14: Total de hombres con alguna prueba de tamizacion para cáncer de prostata | F14: N/A | G14: 1 | H14: 1 | I14: 27,48% | J14: 0 | K14: 3 | L14: 1 | V14: =SUM(J14:U14) -> 4 | W14: =V14/V13 -> 0.4
A15: DT Prostata | B15: COBERTURA BIOPSIA DE PROSTATA | C15: Proporción de hombres con pruebas de tamizaje anormal a quienes se les realizó biopsia de próstata | D15: Número de hombres con resultado anormal en pruebas de tamizaje para cáncer de próstata (PSA o tacto rectal) a quienes se les realizó biopsia de próstata durante el período de medición | E15: Total de hombres con resultado anormal en pruebas de tamizaje para cáncer de próstata durante el mismo período de medición, que según criterio clínico requerían biopsia prostática | F15: N/A | G15: 1 | H15: 1 | J15: 0 | K15: 0 | L15: 0 | V15: =SUM(J15:U15) -> 0 | W15: =V15/V14 -> 0
A16: DT Colon y Recto | B16: COBERTURA TAMIZACION SANGRE OCULTA EN HECES | C16: Proporción de personas entre 50 y 75 años tamizadas para cáncer de colon y recto (sangre oculta en materia fecal con inmunoquímica) | D16: Número de personas entre 50 y 75 años a quienes se les realizó prueba de sangre oculta en materia fecal por método inmunoquímico. | E16: Total de personas entre 50 y 75 años en el municipio | F16: 3010 | G16: 0.5 | H16: =F16*0.5 -> 1505 | I16: 24,65% | J16: 64 | K16: 91 | L16: 1 | V16: =SUM(J16:U16) -> 156 | W16: =V16/H16 -> 0.10365449 | X16: 2992
A17: DT Colon y Recto | B17: POSITIVIDAD SANGRE OCULTA EN HECES | C17: Proporción de personas con pruebas anormal de sangre oculta en heces. | D17: Total de personas entre 50 y 75 años con tamizaje resultado positivo de sangre oculta. | E17: Total de personas entre 50 y 75 años con tamizaje de sangre oculta en heces | F17: N/A | G17: 1 | H17: 1 | J17: 1 | K17: 7 | L17: 0 | V17: =SUM(J17:U17) -> 8 | W17: =V17/V16 -> 0.051282051
A18: DT Colon y Recto | B18: COBERTURA COLONOSCOPIA | C18: Proporción de personas mayores de 50 años con test de sangre oculta en materia fecal positivos a los que se les realizó colonoscopia | D18: Número de personas de 50 años o más con resultado positivo en la prueba de sangre oculta en materia fecal a quienes se les realizó colonoscopia diagnóstica posterior al resultado positivo, durante el período de medición | E18: Total de personas de 50 años o más con resultado positivo en la prueba de sangre oculta en materia fecal durante el mismo período de medición, que requerían colonoscopia diagnóstica según el lineamiento técnico | F18: N/A | G18: 1 | H18: 1 | J18: 0 | K18: 0 | L18: 0 | V18: =SUM(J18:U18) -> 0 | W18: =V18/V17 -> 0
A21: Seguimiento
A22: 46129 | B22: Pacientes con citologia anormal sin reporte de colposcopia
B23: falta indicadoress mes de marzo
B24: En el mes de febrero cambio de prestador
B25: No se cuenta con soporte de biopsia para pacientes positivos por PSA
B26: No se cuenta con reportees de colonoscopia para usuarios con SOMF positivos

Sheet Salud Total
A1: PROGRAMA | B1: TIPO INDICADOR | C1: NOMBRE INDICADOR | D1: NUMERADOR | E1: DENOMINADOR | F1: POBLACION CORTE 31/12/2025 | G1: ESTIMACION | H1: META AÑO 2026 | I1: LINEA BASE 2025 | J1: ENERO | K1: FEBRERO | L1: MARZO | M1: ABRIL | N1: MAYO | O1: JUNIO | P1: JULIO | Q1: AGOSTO | R1: SEPTIEMBRE | S1: OCTUBRE | T1: NOVIEMBRE | U1: DICIEMBRE | V1: ACUMULADO ACTIVIDADES | W1: % EJECUCION
A2: DT cervix | B2: COBERTURA CCU | C2: Proporción de mujeres entre 25 y 29 años tamizadas para cáncer de cuello uterino con citologia cervico uterina. | D2: # Mujeres de 25 a 29 años, con toma de citologia cervico uterina en el periodo evaluado. | E2: Total de mujeres entre 25 y 29 años afiliadas a la EAPB en el municipio | F2: 274 | G2: 0.33 | H2: =F2*0.33 -> 90.42 | I2: 65,4% | J2: 93 | K2: 34 | L2: 39 | V2: =SUM(J2:U2) -> 166 | W2: =V2/H2 -> 1.835877
A3: DT cervix | B3: POSITIVIDAD CCU | C3: Proporción de citologias anormales en mujeres de 25 a 65 años en el periodo evaluado. | D3: # Mujeres de 25 a 65 años con citologia cervico uterina anormal o citologia de triage anormal en el periodo evaluado. | E3: Total de mujeres tamizadas con citologia cervico uterina o citologia de triage en el periodo evaluado. | F3: N/A | G3: 1 | H3: 1 | J3: 0 | K3: 0 | L3: 0 | V3: =SUM(J3:U3) -> 0 | W3: =V3/V2 -> 0
A4: DT cervix | B4: COBERTURA ADN VPH | C4: Proporción de mujeres entre 30 y 65 años tamizadas para cáncer de cuello uterino con ADN-VPH, según esquema en el periodo evaluado. | D4: # Mujeres de 30 a 65 años tamizadas con ADN VPH. | E4: Total de mujeres entre 30 y 65 años afiliadas a la EAPB en el municipio | F4: 2238 | G4: 0.2 | H4: =F4*0.2 -> 447.6 | I4: 18,41% | J4: 36 | K4: 10 | L4: 28 | V4: =SUM(J4:U4) -> 74 | W4: =V4/H4 -> 0.16532618
A5: DT cervix | B5: POSITIVIDAD ADN VPH | C5: Proporción de ADN VPH Positivo en el periodo evaluado | D5: Número de mujeres entre 30 y 65 años con resultado positivo para ADN-VPH durante el período de medición. | E5: Total de mujeres entre 30 y 65 años con resultado de ADN -VPH durante el periodo en revision | F5: N/A | G5: 1 | H5: 1 | J5: 0 | K5: 1 | L5: 1 | V5: =SUM(J5:U5) -> 2 | W5: =V5/V4 -> 0.027027027
A6: DT cervix | B6: COBERTURA COLPOSCOPIA Y BIOPSIA | C6: Proporción de mujeres con citología anormal o citología de triage anormal a quienes se realizó colposcopia y biopsia | D6: Número de mujeres con resultado colposcopia y biopsia cervical, durante el período de medición. | E6: Total de mujeres con citología anormal o citología de triage anormal durante el mismo período de medición, requerían colposcopia y biopsia. | F6: N/A | G6: 1 | H6: 1 | J6: 0 | K6: 1 | L6: 1 | V6: =SUM(J6:U6) -> 2 | W6: =V6/V3 -> #DIV/0!
A7: DT mama | B7: COBERTURA EXAMEN CLINICO DE LA MAMA | C7: Proporción de mujeres entre 40 y 69 años tamizadas con examen clínico de la mama en el periodo evaluado | D7: Número de mujeres entre 40 y 69 años a quienes se les realizó examen clínico de la mama en el periodo evaluado. | E7: Total de mujeres entre 40 y 69 años afiliadas a la EAPB en el municipio | F7: 1778 | G7: 1 | H7: =F7*1 -> 1778 | J7: 46 | K7: 32 | L7: 46 | V7: =SUM(J7:U7) -> 124 | W7: =V7/H7 -> 0.069741282
A8: DT mama | B8: COBERTURA MAMOGRAFIA | C8: Proporción de mujeres entre 50 y 69 años tamizadas para cáncer de mama con mamografía en el periodo evaluado. | D8: Número de mujeres entre 50 y 69 años a quienes se les realizó toma de mamografia. | E8: Total de mujeres entre 50 y 69 años afiliadas a la EAPB en el municipio | F8: 1053 | G8: 0.5 | H8: =F8*0.5 -> 526.5 | I8: 50,24% | J8: 37 | K8: 24 | L8: 89 | V8: =SUM(J8:U8) -> 150 | W8: =V8/H8 -> 0.28490028
A9: DT mama | B9: POSITIVIDAD MAMOGRAFIA | C9: Proporción de mujeres entre 50 y 69 años tamizadas para cáncer de mama con reporte anormal de mamografía en el periodo evaluado. | D9: Número de mujeres entre 50 y 69 años con resultado de mamografia BI-RADS 4 o más | E9: Total de mujeres entre 50 y 69 años con toma de mamografia | F9: N/A | G9: 1 | H9: 1 | J9: 1 | K9: 0 | L9: 0 | V9: =SUM(J9:U9) -> 1 | W9: =V9/V8 -> 0.0066666667
A10: DT mama | B10: COBERTURA BIOPSIA DE MAMA | C10: Proporción de mujeres con resultados de Biopsia de mama. | D10: Número de mujeres con mamografía reportada como BI-RADS 4, o más quienes se les realizó biopsia, durante el período evaluado. | E10: Total de mujeres con mamografía clasificada como BI-RADS 4 o superior, que requerían biopsia diagnóstica, durante el mismo período de medición. | F10: N/A | G10: 1 | H10: 1 | J10: 1 | K10: 0 | L10: 0 | V10: =SUM(J10:U10) -> 1 | W10: =V10/V8 -> 0.0066666667
A11: DT Prostata | B11: COBERTURA TACTO RECTAL | C11: Proporción de hombres entre 50 y 75 años con tacto rectal | D11: Número de hombres entre 50 y 75 años a quienes se les realizó tacto rectal durante el período de medición | E11: Total de hombres entre 50 y 75 años afiliados a la EAPB en el municipio | F11: 1061 | G11: 0.2 | H11: =F11*0.2 -> 212.2 | I11: 57,55% | J11: 16 | K11: 33 | L11: 38 | V11: =SUM(J11:U11) -> 87 | W11: =V11/H11 -> 0.40999057
A12: DT Prostata | B12: COBERTURA PSA | C12: Proporción de hombres entre 50 y 75 años tamizados con PSA | D12: Número de hombres entre 50 y 75 años a quienes se les realizó PSA durante el período de medición | E12: Total de hombres entre 50 y 75 años afiliados a la EAPB en el municipio | F12: 1061 | G12: 0.2 | H12: =F12*0.2 -> 212.2 | I12: 62,86% | J12: 56 | K12: 89 | L12: 101 | V12: =SUM(J12:U12) -> 246 | W12: =V12/H12 -> 1.1592837
A13: DT Prostata | B13: COBERTURA (PSA Y TACTO RECTAL) | C13: Proporción de hombres mayores de 50 años con tamizaje combinado para cáncer de próstata (PSA y Tacto Rectal) | D13: Número de hombres entre 50 y 75 años a quienes se les realizó tamizaje combinado (PSA y tacto rectal) durante el período de medición | E13: Total de hombres entre 50 y 75 años afiliados a la EAPB en el municipio | F13: 1061 | G13: 0.2 | H13: =F13*0.2 -> 212.2 | I13: 20,29% | J13: 72 | K13: 122 | L13: 139 | V13: =SUM(J13:U13) -> 333 | W13: =V13/H13 -> 1.5692743
A14: DT Prostata | B14: POSITIVIDAD CANCER DE PROSTATA | C14: Proporción de hombres mayores de 50 años con tamizacion de cancer de prostata resultado anormal | D14: Numero de hombres con resultado anormal de tamizacion para cancer de prostata en el periodo evaluado. | E14: Total de hombres con alguna prueba de tamizacion para cáncer de prostata | F14: N/A | G14: 1 | H14: 1 | J14: 0 | K14: 0 | L14: 0 | V14: =SUM(J14:U14) -> 0 | W14: =V14/V13 -> 0
A15: DT Prostata | B15: COBERTURA BIOPSIA DE PROSTATA | C15: Proporción de hombres con pruebas de tamizaje anormal a quienes se les realizó biopsia de próstata | D15: Número de hombres con resultado anormal en pruebas de tamizaje para cáncer de próstata (PSA o tacto rectal) a quienes se les realizó biopsia de próstata durante el período de medición | E15: Total de hombres con resultado anormal en pruebas de tamizaje para cáncer de próstata durante el mismo período de medición, que según criterio clínico requerían biopsia prostática | F15: N/A | G15: 1 | H15: 1 | J15: 0 | K15: 0 | L15: 0 | V15: =SUM(J15:U15) -> 0 | W15: =V15/V14 -> #DIV/0!
A16: DT Colon y Recto | B16: COBERTURA TAMIZACION SANGRE OCULTA EN HECES | C16: Proporción de personas entre 50 y 75 años tamizadas para cáncer de colon y recto (sangre oculta en materia fecal con inmunoquímica) | D16: Número de personas entre 50 y 75 años a quienes se les realizó prueba de sangre oculta en materia fecal por método inmunoquímico. | E16: Total de personas entre 50 y 75 años en el municipio | F16: 2291 | G16: 0.5 | H16: =F16*0.5 -> 1145.5 | I16: 45,44% | J16: 44 | K16: 145 | L16: 135 | V16: =SUM(J16:U16) -> 324 | W16: =V16/H16 -> 0.28284592
A17: DT Colon y Recto | B17: POSITIVIDAD SANGRE OCULTA EN HECES | C17: Proporción de personas con pruebas anormal de sangre oculta en heces. | D17: Total de personas entre 50 y 75 años con tamizaje resultado positivo de sangre oculta. | E17: Total de personas entre 50 y 75 años con tamizaje de sangre oculta en heces | F17: N/A | G17: 1 | H17: 1 | J17: 0 | K17: 0 | L17: 0 | V17: =SUM(J17:U17) -> 0 | W17: =V17/V16 -> 0
A18: DT Colon y Recto | B18: COBERTURA COLONOSCOPIA | C18: Proporción de personas mayores de 50 años con test de sangre oculta en materia fecal positivos a los que se les realizó colonoscopia | D18: Número de personas de 50 años o más con resultado positivo en la prueba de sangre oculta en materia fecal a quienes se les realizó colonoscopia diagnóstica posterior al resultado positivo, durante el período de medición | E18: Total de personas de 50 años o más con resultado positivo en la prueba de sangre oculta en materia fecal durante el mismo período de medición, que requerían colonoscopia diagnóstica según el lineamiento técnico | F18: N/A | G18: 1 | H18: 1 | J18: 0 | K18: 0 | L18: 0 | V18: =SUM(J18:U18) -> 0 | W18: =V18/V17 -> #DIV/0!

Sheet Proteger
A1: PROGRAMA | B1: TIPO INDICADOR | C1: NOMBRE INDICADOR | D1: NUMERADOR | E1: DENOMINADOR | F1: POBLACION CORTE 31/12/2025 | G1: ESTIMACION | H1: META AÑO 2026 | I1: LINEA BASE 2025 | J1: ENERO | K1: FEBRERO | L1: MARZO | M1: ABRIL | N1: MAYO | O1: JUNIO | P1: JULIO | Q1: AGOSTO | R1: SEPTIEMBRE | S1: OCTUBRE | T1: NOVIEMBRE | U1: DICIEMBRE | V1: ACUMULADO ACTIVIDADES | W1: % EJECUCION
A2: DT cervix | B2: COBERTURA CCU | C2: Proporción de mujeres entre 25 y 29 años tamizadas para cáncer de cuello uterino con citologia cervico uterina. | D2: # Mujeres de 25 a 29 años, con toma de citologia cervico uterina en el periodo evaluado. | E2: Total de mujeres entre 25 y 29 años afiliadas a la EAPB en el municipio | F2: 41 | G2: 0.33 | H2: =F2*0.33 -> 13.53 | I2: 75,6 | J2: 2 | K2: 6 | L2: 8 | V2: =SUM(J2:U2) -> 16 | W2: =V2/H2 -> 1.1825573
A3: DT cervix | B3: POSITIVIDAD CCU | C3: Proporción de citologias anormales en mujeres de 25 a 65 años en el periodo evaluado. | D3: # Mujeres de 25 a 65 años con citologia cervico uterina anormal o citologia de triage anormal en el periodo evaluado. | E3: Total de mujeres tamizadas con citologia cervico uterina o citologia de triage en el periodo evaluado. | F3: N/A | G3: 1 | H3: 1 | J3: 0 | K3: 0 | L3: 0 | V3: =SUM(J3:U3) -> 0 | W3: =V3/V2 -> 0
A4: DT cervix | B4: COBERTURA ADN VPH | C4: Proporción de mujeres entre 30 y 65 años tamizadas para cáncer de cuello uterino con ADN-VPH, según esquema en el periodo evaluado. | D4: # Mujeres de 30 a 65 años tamizadas con ADN VPH. | E4: Total de mujeres entre 30 y 65 años afiliadas a la EAPB en el municipio | F4: 294 | G4: 0.2 | H4: =F4*0.2 -> 58.8 | I4: 0 | J4: 0 | K4: 2 | L4: 3 | V4: =SUM(J4:U4) -> 5 | W4: =V4/H4 -> 0.085034014
A5: DT cervix | B5: POSITIVIDAD ADN VPH | C5: Proporción de ADN VPH Positivo en el periodo evaluado | D5: Número de mujeres entre 30 y 65 años con resultado positivo para ADN-VPH durante el período de medición. | E5: Total de mujeres entre 30 y 65 años con resultado de ADN -VPH durante el periodo en revision | F5: N/A | G5: 1 | H5: 1 | J5: 0 | K5: 0 | L5: 0 | V5: =SUM(J5:U5) -> 0 | W5: =V5/V4 -> 0
A6: DT cervix | B6: COBERTURA COLPOSCOPIA Y BIOPSIA | C6: Proporción de mujeres con citología anormal o citología de triage anormal a quienes se realizó colposcopia y biopsia | D6: Número de mujeres con resultado colposcopia y biopsia cervical, durante el período de medición. | E6: Total de mujeres con citología anormal o citología de triage anormal durante el mismo período de medición, requerían colposcopia y biopsia. | F6: N/A | G6: 1 | H6: 1 | J6: 1 | K6: 1 | L6: 1 | V6: =SUM(J6:U6) -> 3 | W6: =V6/V3 -> #DIV/0!
A7: DT mama | B7: COBERTURA EXAMEN CLINICO DE LA MAMA | C7: Proporción de mujeres entre 40 y 69 años tamizadas con examen clínico de la mama en el periodo evaluado | D7: Número de mujeres entre 40 y 69 años a quienes se les realizó examen clínico de la mama en el periodo evaluado. | E7: Total de mujeres entre 40 y 69 años afiliadas a la EAPB en el municipio | F7: 206 | G7: 1 | H7: =F7*1 -> 206 | J7: 1 | K7: 5 | L7: 4 | V7: =SUM(J7:U7) -> 10 | W7: =V7/H7 -> 0.048543689
A8: DT mama | B8: COBERTURA MAMOGRAFIA | C8: Proporción de mujeres entre 50 y 69 años tamizadas para cáncer de mama con mamografía en el periodo evaluado. | D8: Número de mujeres entre 50 y 69 años a quienes se les realizó toma de mamografia. | E8: Total de mujeres entre 50 y 69 años afiliadas a la EAPB en el municipio | F8: 96 | G8: 0.5 | H8: =F8*0.5 -> 48 | I8: 45,45% | J8: 7 | K8: 6 | L8: 5 | V8: =SUM(J8:U8) -> 18 | W8: =V8/H8 -> 0.375
A9: DT mama | B9: POSITIVIDAD MAMOGRAFIA | C9: Proporción de mujeres entre 50 y 69 años tamizadas para cáncer de mama con reporte anormal de mamografía en el periodo evaluado. | D9: Número de mujeres entre 50 y 69 años con resultado de mamografia BI-RADS 4 o más | E9: Total de mujeres entre 50 y 69 años con toma de mamografia | F9: N/A | G9: 1 | H9: 1 | J9: 0 | K9: 1 | L9: 0 | V9: =SUM(J9:U9) -> 1 | W9: =V9/V8 -> 0.055555556
A10: DT mama | B10: COBERTURA BIOPSIA DE MAMA | C10: Proporción de mujeres con resultados de Biopsia de mama. | D10: Número de mujeres con mamografía reportada como BI-RADS 4, o más quienes se les realizó biopsia, durante el período evaluado. | E10: Total de mujeres con mamografía clasificada como BI-RADS 4 o superior, que requerían biopsia diagnóstica, durante el mismo período de medición. | F10: N/A | G10: 1 | H10: 1 | J10: 0 | K10: 0 | L10: 1 | V10: =SUM(J10:U10) -> 1 | W10: =V10/V8 -> 0.055555556
A11: DT Prostata | B11: COBERTURA TACTO RECTAL | C11: Proporción de hombres entre 50 y 75 años con tacto rectal | D11: Número de hombres entre 50 y 75 años a quienes se les realizó tacto rectal durante el período de medición | E11: Total de hombres entre 50 y 75 años afiliados a la EAPB en el municipio | F11: 87 | G11: 0.2 | H11: =F11*0.2 -> 17.4 | I11: 39,44% | J11: 0 | K11: 3 | L11: 4 | V11: =SUM(J11:U11) -> 7 | W11: =V11/H11 -> 0.40229885
A12: DT Prostata | B12: COBERTURA PSA | C12: Proporción de hombres entre 50 y 75 años tamizados con PSA | D12: Número de hombres entre 50 y 75 años a quienes se les realizó PSA durante el período de medición | E12: Total de hombres entre 50 y 75 años afiliados a la EAPB en el municipio | F12: 87 | G12: 0.2 | H12: =F12*0.2 -> 17.4 | I12: 19,72% | J12: 8 | K12: 2 | L12: 3 | V12: =SUM(J12:U12) -> 13 | W12: =V12/H12 -> 0.74712644
A13: DT Prostata | B13: COBERTURA (PSA Y TACTO RECTAL) | C13: Proporción de hombres mayores de 50 años con tamizaje combinado para cáncer de próstata (PSA y Tacto Rectal) | D13: Número de hombres entre 50 y 75 años a quienes se les realizó tamizaje combinado (PSA y tacto rectal) durante el período de medición | E13: Total de hombres entre 50 y 75 años afiliados a la EAPB en el municipio | F13: 87 | G13: 0.2 | H13: =F13*0.2 -> 17.4 | I13: 16,90% | J13: 0 | K13: 1 | L13: 1 | V13: =SUM(J13:U13) -> 2 | W13: =V13/H13 -> 0.11494253
A14: DT Prostata | B14: POSITIVIDAD CANCER DE PROSTATA | C14: Proporción de hombres mayores de 50 años con tamizacion de cancer de prostata resultado anormal | D14: Numero de hombres con resultado anormal de tamizacion para cancer de prostata en el periodo evaluado. | E14: Total de hombres con alguna prueba de tamizacion para cáncer de prostata | F14: N/A | G14: 1 | H14: 1 | J14: 0 | K14: 0 | L14: 0 | V14: =SUM(J14:U14) -> 0 | W14: =V14/V13 -> 0
A15: DT Prostata | B15: COBERTURA BIOPSIA DE PROSTATA | C15: Proporción de hombres con pruebas de tamizaje anormal a quienes se les realizó biopsia de próstata | D15: Número de hombres con resultado anormal en pruebas de tamizaje para cáncer de próstata (PSA o tacto rectal) a quienes se les realizó biopsia de próstata durante el período de medición | E15: Total de hombres con resultado anormal en pruebas de tamizaje para cáncer de próstata durante el mismo período de medición, que según criterio clínico requerían biopsia prostática | F15: N/A | G15: 1 | H15: 1 | J15: 0 | K15: 0 | L15: 0 | V15: =SUM(J15:U15) -> 0 | W15: =V15/V14 -> #DIV/0!
A16: DT Colon y Recto | B16: COBERTURA TAMIZACION SANGRE OCULTA EN HECES | C16: Proporción de personas entre 50 y 75 años tamizadas para cáncer de colon y recto (sangre oculta en materia fecal con inmunoquímica) | D16: Número de personas entre 50 y 75 años a quienes se les realizó prueba de sangre oculta en materia fecal por método inmunoquímico. | E16: Total de personas entre 50 y 75 años en el municipio | F16: 197 | G16: 0.5 | H16: =F16*0.5 -> 98.5 | I16: 0.5 | J16: 4 | K16: 3 | L16: 3 | V16: =SUM(J16:U16) -> 10 | W16: =V16/H16 -> 0.10152284
A17: DT Colon y Recto | B17: POSITIVIDAD SANGRE OCULTA EN HECES | C17: Proporción de personas con pruebas anormal de sangre oculta en heces. | D17: Total de personas entre 50 y 75 años con tamizaje resultado positivo de sangre oculta. | E17: Total de personas entre 50 y 75 años con tamizaje de sangre oculta en heces | F17: N/A | G17: 1 | H17: 1 | J17: 0 | K17: 0 | L17: 0 | V17: =SUM(J17:U17) -> 0 | W17: =V17/V16 -> 0
A18: DT Colon y Recto | B18: COBERTURA COLONOSCOPIA | C18: Proporción de personas mayores de 50 años con test de sangre oculta en materia fecal positivos a los que se les realizó colonoscopia | D18: Número de personas de 50 años o más con resultado positivo en la prueba de sangre oculta en materia fecal a quienes se les realizó colonoscopia diagnóstica posterior al resultado positivo, durante el período de medición | E18: Total de personas de 50 años o más con resultado positivo en la prueba de sangre oculta en materia fecal durante el mismo período de medición, que requerían colonoscopia diagnóstica según el lineamiento técnico | F18: N/A | G18: 1 | H18: 1 | J18: 0 | K18: 0 | L18: 0 | V18: =SUM(J18:U18) -> 0 | W18: =V18/V17 -> #DIV/0!

Sheet Consolidado
A1: PROGRAMA | B1: TIPO INDICADOR | C1: NOMBRE INDICADOR | D1: NUMERADOR | E1: DENOMINADOR | F1: POBLACION CORTE 31/12/2025 activos soogamoso | G1: LINEA BASE 2025 | H1: Nueva EPS | I1: Sanitas | J1: Coosalud | K1: Famisanar | L1: Salud total | M1: Cajacopi | N1: sumatoria | O1: Avance en el cumplimiento | P1: Cumplimiento
A2: DT cervix | B2: COBERTURA CCU | C2: Proporción de mujeres entre 25 y 29 años tamizadas para cáncer de cuello uterino con citologia cervico uterina. | D2: # Mujeres de 25 a 29 años, con toma de citologia cervico uterina en el periodo evaluado. | E2: Total de mujeres entre 25 y 29 años afiliadas a la EAPB en el municipio | F2: =SUM('Nueva EPS'!F2+Sanitas!F4+Coosalud!F2+Famisanar!F2+'Salud Total'!F2+Proteger!F2) -> 14212 | G2: 64,71% | H2: ='Nueva EPS'!W2 -> 0.1388574 | I2: =Sanitas!W2 -> 1.077178 | J2: =Coosalud!W2 -> 0.23148148 | K2: =Famisanar!W2 -> 0.087154733 | L2: ='Salud Total'!W2 -> 1.835877 | M2: =Proteger!W2 -> 1.1825573 | N2: =SUM(H2:M2) -> 4.5531059 | O2: =AVERAGE(H2:M2) -> 0.75885099
A3: DT cervix | B3: POSITIVIDAD CCU | C3: Proporción de citologias anormales en mujeres de 25 a 65 años en el periodo evaluado. | D3: # Mujeres de 25 a 65 años con citologia cervico uterina anormal o citologia de triage anormal en el periodo evaluado. | E3: Total de mujeres tamizadas con citologia cervico uterina o citologia de triage en el periodo evaluado. | F3: N/A | H3: ='Nueva EPS'!W3 -> 0.034013605 | I3: =Sanitas!W3 -> 0.0065934066 | J3: =Coosalud!W3 -> 0.12121212 | K3: =Famisanar!W3 -> 0.30769231 | L3: ='Salud Total'!W3 -> 0 | M3: =Proteger!W3 -> 0 | O3: =AVERAGE(H3:M3) -> 0.078251907
A4: DT cervix | B4: COBERTURA ADN VPH | C4: Proporción de mujeres entre 30 y 65 años tamizadas para cáncer de cuello uterino con ADN-VPH, según esquema en el periodo evaluado. | D4: # Mujeres de 30 a 65 años tamizadas con ADN VPH. | E4: Total de mujeres entre 30 y 65 años afiliadas a la EAPB en el municipio | F4: =SUM('Nueva EPS'!F4+Sanitas!F4+Coosalud!F4+Famisanar!F4+'Salud Total'!F4+Proteger!F4) -> 36807 | G4: 13,19% | H4: ='Nueva EPS'!W4 -> 0.011169025 | I4: =Sanitas!W4 -> 0.0030596634 | J4: =Coosalud!W4 -> 0.10200154 | K4: =Famisanar!W4 -> 0.092833876 | L4: ='Salud Total'!W4 -> 0.16532618 | M4: =Proteger!W4 -> 0.085034014 | N4: =SUM(H4:M4) -> 0.4594243 | O4: =AVERAGE(H4:M4) -> 0.076570717
A5: DT cervix | B5: POSITIVIDAD ADN VPH | C5: Proporción de ADN VPH Positivo en el periodo evaluado | D5: Número de mujeres entre 30 y 65 años con resultado positivo para ADN-VPH durante el período de medición. | E5: Total de mujeres entre 30 y 65 años con resultado de ADN -VPH durante el periodo en revision | F5: N/A | H5: ='Nueva EPS'!W5 -> 0.4047619 | I5: =Sanitas!W5 -> 0 | J5: =Coosalud!W5 -> 0.037735849 | K5: =Famisanar!W5 -> 0.10526316 | L5: ='Salud Total'!W5 -> 0.027027027 | M5: =Proteger!W5 -> 0 | N5: =SUM(H5:M5) -> 0.57478794 | O5: =AVERAGE(H5:M5) -> 0.09579799
A6: DT cervix | B6: COBERTURA COLPOSCOPIA Y BIOPSIA | C6: Proporción de mujeres con citología anormal o citología de triage anormal a quienes se realizó colposcopia y biopsia | D6: Número de mujeres con resultado colposcopia y biopsia cervical, durante el período de medición. | E6: Total de mujeres con citología anormal o citología de triage anormal durante el mismo período de medición, requerían colposcopia y biopsia. | F6: N/A | H6: ='Nueva EPS'!W6 -> 1 | I6: =Sanitas!W6 -> 0 | J6: =Coosalud!W6 -> 0.25 | K6: =Famisanar!W6 -> 0.75 | L6: ='Salud Total'!W6 -> #DIV/0! | M6: =Proteger!W6 -> #DIV/0! | N6: =SUM(H6:M6) -> #DIV/0! | O6: =AVERAGE(H6:M6) -> #DIV/0!
A7: DT mama | B7: COBERTURA EXAMEN CLINICO DE LA MAMA | C7: Proporción de mujeres entre 40 y 69 años tamizadas con examen clínico de la mama en el periodo evaluado | D7: Número de mujeres entre 40 y 69 años a quienes se les realizó examen clínico de la mama en el periodo evaluado. | E7: Total de mujeres entre 40 y 69 años afiliadas a la EAPB en el municipio | F7: =SUM('Nueva EPS'!F7+Sanitas!F7+Coosalud!F7+Famisanar!F7+'Salud Total'!F7+Proteger!F7) -> 28215 | H7: ='Nueva EPS'!W7 -> 0.06420719 | I7: =Sanitas!W7 -> 0.0048944204 | J7: =Coosalud!W7 -> 0.061394381 | K7: =Famisanar!W7 -> 0.35220935 | L7: ='Salud Total'!W7 -> 0.069741282 | M7: =Proteger!W7 -> 0.048543689 | N7: =SUM(H7:M7) -> 0.60099031 | O7: =AVERAGE(H7:M7) -> 0.10016505
A8: DT mama | B8: COBERTURA MAMOGRAFIA | C8: Proporción de mujeres entre 50 y 69 años tamizadas para cáncer de mama con mamografía en el periodo evaluado. | D8: Número de mujeres entre 50 y 69 años a quienes se les realizó toma de mamografia. | E8: Total de mujeres entre 50 y 69 años afiliadas a la EAPB en el municipio | F8: =SUM('Nueva EPS'!F8+Sanitas!F8+Coosalud!F8+Famisanar!F8+'Salud Total'!F8+Proteger!F8) -> 17438 | G8: 52,99% | H8: ='Nueva EPS'!W8 -> 0.10810269 | I8: =Sanitas!W8 -> 0.14322251 | J8: =Coosalud!W8 -> 0.08 | K8: =Famisanar!W8 -> 0.25525526 | L8: ='Salud Total'!W8 -> 0.28490028 | M8: =Proteger!W8 -> 0.375 | N8: =SUM(H8:M8) -> 1.2464807 | O8: =AVERAGE(H8:M8) -> 0.20774679
A9: DT mama | B9: POSITIVIDAD MAMOGRAFIA | C9: Proporción de mujeres entre 50 y 69 años tamizadas para cáncer de mama con reporte anormal de mamografía en el periodo evaluado. | D9: Número de mujeres entre 50 y 69 años con resultado de mamografia BI-RADS 4 o más | E9: Total de mujeres entre 50 y 69 años con toma de mamografia | F9: N/A | H9: ='Nueva EPS'!W9 -> 0.0018552876 | I9: =Sanitas!W9 -> 0.0035714286 | J9: =Coosalud!W9 -> 0 | K9: =Famisanar!W9 -> 0 | L9: ='Salud Total'!W9 -> 0.0066666667 | M9: =Proteger!W9 -> 0.055555556 | N9: =SUM(H9:M9) -> 0.067648938 | O9: =AVERAGE(H9:M9) -> 0.011274823
